2024-04-12 00:51:48,462 INFO    StreamThr :201578 [internal.py:wandb_internal():86] W&B internal server running at pid: 201578, started at: 2024-04-12 00:51:48.462126
2024-04-12 00:51:48,464 DEBUG   HandlerThread:201578 [handler.py:handle_request():146] handle_request: status
2024-04-12 00:51:48,465 INFO    WriterThread:201578 [datastore.py:open_for_write():87] open: ./wandb/run-20240412_005148-iid24wa3/run-iid24wa3.wandb
2024-04-12 00:51:48,466 DEBUG   SenderThread:201578 [sender.py:send():379] send: header
2024-04-12 00:51:48,467 DEBUG   SenderThread:201578 [sender.py:send():379] send: run
2024-04-12 00:51:48,469 INFO    SenderThread:201578 [sender.py:_setup_resume():749] checking resume status for None/SG_VLM/iid24wa3
2024-04-12 00:51:53,468 DEBUG   HandlerThread:201578 [handler.py:handle_request():146] handle_request: keepalive
2024-04-12 00:51:58,468 DEBUG   HandlerThread:201578 [handler.py:handle_request():146] handle_request: keepalive
2024-04-12 00:52:03,469 DEBUG   HandlerThread:201578 [handler.py:handle_request():146] handle_request: keepalive
2024-04-12 00:52:08,470 DEBUG   HandlerThread:201578 [handler.py:handle_request():146] handle_request: keepalive
2024-04-12 00:52:13,470 DEBUG   HandlerThread:201578 [handler.py:handle_request():146] handle_request: keepalive
2024-04-12 00:52:18,471 DEBUG   HandlerThread:201578 [handler.py:handle_request():146] handle_request: keepalive
2024-04-12 00:52:23,472 DEBUG   HandlerThread:201578 [handler.py:handle_request():146] handle_request: keepalive
2024-04-12 00:52:28,472 DEBUG   HandlerThread:201578 [handler.py:handle_request():146] handle_request: keepalive
2024-04-12 00:52:33,473 DEBUG   HandlerThread:201578 [handler.py:handle_request():146] handle_request: keepalive
2024-04-12 00:52:38,474 DEBUG   HandlerThread:201578 [handler.py:handle_request():146] handle_request: keepalive
2024-04-12 00:52:43,474 DEBUG   HandlerThread:201578 [handler.py:handle_request():146] handle_request: keepalive
2024-04-12 00:52:48,475 DEBUG   HandlerThread:201578 [handler.py:handle_request():146] handle_request: keepalive
2024-04-12 00:52:51,915 INFO    SenderThread:201578 [retry.py:__call__():172] Retry attempt failed:
Traceback (most recent call last):
  File "/home/liushuai1/anaconda3/envs/tapa/lib/python3.10/site-packages/urllib3/connection.py", line 174, in _new_conn
    conn = connection.create_connection(
  File "/home/liushuai1/anaconda3/envs/tapa/lib/python3.10/site-packages/urllib3/util/connection.py", line 95, in create_connection
    raise err
  File "/home/liushuai1/anaconda3/envs/tapa/lib/python3.10/site-packages/urllib3/util/connection.py", line 85, in create_connection
    sock.connect(sa)
TimeoutError: timed out

During handling of the above exception, another exception occurred:

Traceback (most recent call last):
  File "/home/liushuai1/anaconda3/envs/tapa/lib/python3.10/site-packages/urllib3/connectionpool.py", line 703, in urlopen
    httplib_response = self._make_request(
  File "/home/liushuai1/anaconda3/envs/tapa/lib/python3.10/site-packages/urllib3/connectionpool.py", line 386, in _make_request
    self._validate_conn(conn)
  File "/home/liushuai1/anaconda3/envs/tapa/lib/python3.10/site-packages/urllib3/connectionpool.py", line 1042, in _validate_conn
    conn.connect()
  File "/home/liushuai1/anaconda3/envs/tapa/lib/python3.10/site-packages/urllib3/connection.py", line 358, in connect
    self.sock = conn = self._new_conn()
  File "/home/liushuai1/anaconda3/envs/tapa/lib/python3.10/site-packages/urllib3/connection.py", line 179, in _new_conn
    raise ConnectTimeoutError(
urllib3.exceptions.ConnectTimeoutError: (<urllib3.connection.HTTPSConnection object at 0x7f30ee796380>, 'Connection to api.wandb.ai timed out. (connect timeout=20)')

During handling of the above exception, another exception occurred:

Traceback (most recent call last):
  File "/home/liushuai1/anaconda3/envs/tapa/lib/python3.10/site-packages/requests/adapters.py", line 489, in send
    resp = conn.urlopen(
  File "/home/liushuai1/anaconda3/envs/tapa/lib/python3.10/site-packages/urllib3/connectionpool.py", line 787, in urlopen
    retries = retries.increment(
  File "/home/liushuai1/anaconda3/envs/tapa/lib/python3.10/site-packages/urllib3/util/retry.py", line 592, in increment
    raise MaxRetryError(_pool, url, error or ResponseError(cause))
urllib3.exceptions.MaxRetryError: HTTPSConnectionPool(host='api.wandb.ai', port=443): Max retries exceeded with url: /graphql (Caused by ConnectTimeoutError(<urllib3.connection.HTTPSConnection object at 0x7f30ee796380>, 'Connection to api.wandb.ai timed out. (connect timeout=20)'))

During handling of the above exception, another exception occurred:

Traceback (most recent call last):
  File "/home/liushuai1/anaconda3/envs/tapa/lib/python3.10/site-packages/wandb/sdk/lib/retry.py", line 131, in __call__
    result = self._call_fn(*args, **kwargs)
  File "/home/liushuai1/anaconda3/envs/tapa/lib/python3.10/site-packages/wandb/sdk/internal/internal_api.py", line 369, in execute
    return self.client.execute(*args, **kwargs)  # type: ignore
  File "/home/liushuai1/anaconda3/envs/tapa/lib/python3.10/site-packages/wandb/vendor/gql-0.2.0/wandb_gql/client.py", line 52, in execute
    result = self._get_result(document, *args, **kwargs)
  File "/home/liushuai1/anaconda3/envs/tapa/lib/python3.10/site-packages/wandb/vendor/gql-0.2.0/wandb_gql/client.py", line 60, in _get_result
    return self.transport.execute(document, *args, **kwargs)
  File "/home/liushuai1/anaconda3/envs/tapa/lib/python3.10/site-packages/wandb/sdk/lib/gql_request.py", line 58, in execute
    request = self.session.post(self.url, **post_args)
  File "/home/liushuai1/anaconda3/envs/tapa/lib/python3.10/site-packages/requests/sessions.py", line 635, in post
    return self.request("POST", url, data=data, json=json, **kwargs)
  File "/home/liushuai1/anaconda3/envs/tapa/lib/python3.10/site-packages/requests/sessions.py", line 587, in request
    resp = self.send(prep, **send_kwargs)
  File "/home/liushuai1/anaconda3/envs/tapa/lib/python3.10/site-packages/requests/sessions.py", line 701, in send
    r = adapter.send(request, **kwargs)
  File "/home/liushuai1/anaconda3/envs/tapa/lib/python3.10/site-packages/requests/adapters.py", line 553, in send
    raise ConnectTimeout(e, request=request)
requests.exceptions.ConnectTimeout: HTTPSConnectionPool(host='api.wandb.ai', port=443): Max retries exceeded with url: /graphql (Caused by ConnectTimeoutError(<urllib3.connection.HTTPSConnection object at 0x7f30ee796380>, 'Connection to api.wandb.ai timed out. (connect timeout=20)'))
2024-04-12 00:52:53,476 DEBUG   HandlerThread:201578 [handler.py:handle_request():146] handle_request: keepalive
2024-04-12 00:52:55,165 DEBUG   HandlerThread:201578 [handler.py:handle_request():146] handle_request: shutdown
2024-04-12 00:52:55,165 INFO    HandlerThread:201578 [handler.py:finish():866] shutting down handler
2024-04-12 00:52:55,473 INFO    WriterThread:201578 [datastore.py:close():296] close: ./wandb/run-20240412_005148-iid24wa3/run-iid24wa3.wandb
