2024-04-12 00:51:48,459 INFO    MainThread:200250 [wandb_setup.py:_flush():76] Current SDK version is 0.16.6
2024-04-12 00:51:48,459 INFO    MainThread:200250 [wandb_setup.py:_flush():76] Configure stats pid to 200250
2024-04-12 00:51:48,459 INFO    MainThread:200250 [wandb_setup.py:_flush():76] Loading settings from /home/liushuai1/.config/wandb/settings
2024-04-12 00:51:48,459 INFO    MainThread:200250 [wandb_setup.py:_flush():76] Loading settings from /nvme/liushuai/SG_VLM/wandb/settings
2024-04-12 00:51:48,459 INFO    MainThread:200250 [wandb_setup.py:_flush():76] Loading settings from environment variables: {'project': 'SG_VLM', 'run_name': 'octopus_adapter_04_12_1712854249_initsg_planning', 'api_key': '***REDACTED***'}
2024-04-12 00:51:48,459 INFO    MainThread:200250 [wandb_setup.py:_flush():76] Applying setup settings: {'_disable_service': False}
2024-04-12 00:51:48,459 INFO    MainThread:200250 [wandb_setup.py:_flush():76] Inferring run settings from compute environment: {'program_relpath': 'finetune/OGSG_adapter.py', 'program_abspath': '/nvme/liushuai/SG_VLM/finetune/OGSG_adapter.py', 'program': '/nvme/liushuai/SG_VLM/finetune/OGSG_adapter.py'}
2024-04-12 00:51:48,459 INFO    MainThread:200250 [wandb_setup.py:_flush():76] Applying login settings: {}
2024-04-12 00:51:48,459 INFO    MainThread:200250 [wandb_init.py:_log_setup():521] Logging user logs to ./wandb/run-20240412_005148-iid24wa3/logs/debug.log
2024-04-12 00:51:48,459 INFO    MainThread:200250 [wandb_init.py:_log_setup():522] Logging internal logs to ./wandb/run-20240412_005148-iid24wa3/logs/debug-internal.log
2024-04-12 00:51:48,459 INFO    MainThread:200250 [wandb_init.py:init():561] calling init triggers
2024-04-12 00:51:48,459 INFO    MainThread:200250 [wandb_init.py:init():568] wandb.init called with sweep_config: {}
config: {}
2024-04-12 00:51:48,459 INFO    MainThread:200250 [wandb_init.py:init():611] starting backend
2024-04-12 00:51:48,459 INFO    MainThread:200250 [wandb_init.py:init():615] setting up manager
2024-04-12 00:51:48,461 INFO    MainThread:200250 [backend.py:_multiprocessing_setup():105] multiprocessing start_methods=fork,spawn,forkserver, using: spawn
2024-04-12 00:51:48,461 INFO    MainThread:200250 [wandb_init.py:init():623] backend started and connected
2024-04-12 00:51:48,463 INFO    MainThread:200250 [wandb_init.py:init():715] updated telemetry
2024-04-12 00:51:48,467 INFO    MainThread:200250 [wandb_init.py:init():748] communicating run to backend with 90.0 second timeout
2024-04-12 00:52:47,192 INFO    Thread-3 (wrapped_target):200250 [retry.py:__call__():172] Retry attempt failed:
Traceback (most recent call last):
  File "/home/liushuai1/anaconda3/envs/tapa/lib/python3.10/site-packages/urllib3/connection.py", line 174, in _new_conn
    conn = connection.create_connection(
  File "/home/liushuai1/anaconda3/envs/tapa/lib/python3.10/site-packages/urllib3/util/connection.py", line 95, in create_connection
    raise err
  File "/home/liushuai1/anaconda3/envs/tapa/lib/python3.10/site-packages/urllib3/util/connection.py", line 85, in create_connection
    sock.connect(sa)
TimeoutError: timed out

During handling of the above exception, another exception occurred:

Traceback (most recent call last):
  File "/home/liushuai1/anaconda3/envs/tapa/lib/python3.10/site-packages/urllib3/connectionpool.py", line 703, in urlopen
    httplib_response = self._make_request(
  File "/home/liushuai1/anaconda3/envs/tapa/lib/python3.10/site-packages/urllib3/connectionpool.py", line 386, in _make_request
    self._validate_conn(conn)
  File "/home/liushuai1/anaconda3/envs/tapa/lib/python3.10/site-packages/urllib3/connectionpool.py", line 1042, in _validate_conn
    conn.connect()
  File "/home/liushuai1/anaconda3/envs/tapa/lib/python3.10/site-packages/urllib3/connection.py", line 358, in connect
    self.sock = conn = self._new_conn()
  File "/home/liushuai1/anaconda3/envs/tapa/lib/python3.10/site-packages/urllib3/connection.py", line 179, in _new_conn
    raise ConnectTimeoutError(
urllib3.exceptions.ConnectTimeoutError: (<urllib3.connection.HTTPSConnection object at 0x7f371427a1a0>, 'Connection to api.wandb.ai timed out. (connect timeout=20)')

During handling of the above exception, another exception occurred:

Traceback (most recent call last):
  File "/home/liushuai1/anaconda3/envs/tapa/lib/python3.10/site-packages/requests/adapters.py", line 489, in send
    resp = conn.urlopen(
  File "/home/liushuai1/anaconda3/envs/tapa/lib/python3.10/site-packages/urllib3/connectionpool.py", line 787, in urlopen
    retries = retries.increment(
  File "/home/liushuai1/anaconda3/envs/tapa/lib/python3.10/site-packages/urllib3/util/retry.py", line 592, in increment
    raise MaxRetryError(_pool, url, error or ResponseError(cause))
urllib3.exceptions.MaxRetryError: HTTPSConnectionPool(host='api.wandb.ai', port=443): Max retries exceeded with url: /graphql (Caused by ConnectTimeoutError(<urllib3.connection.HTTPSConnection object at 0x7f371427a1a0>, 'Connection to api.wandb.ai timed out. (connect timeout=20)'))

During handling of the above exception, another exception occurred:

Traceback (most recent call last):
  File "/home/liushuai1/anaconda3/envs/tapa/lib/python3.10/site-packages/wandb/sdk/lib/retry.py", line 131, in __call__
    result = self._call_fn(*args, **kwargs)
  File "/home/liushuai1/anaconda3/envs/tapa/lib/python3.10/site-packages/wandb/sdk/internal/internal_api.py", line 369, in execute
    return self.client.execute(*args, **kwargs)  # type: ignore
  File "/home/liushuai1/anaconda3/envs/tapa/lib/python3.10/site-packages/wandb/vendor/gql-0.2.0/wandb_gql/client.py", line 52, in execute
    result = self._get_result(document, *args, **kwargs)
  File "/home/liushuai1/anaconda3/envs/tapa/lib/python3.10/site-packages/wandb/vendor/gql-0.2.0/wandb_gql/client.py", line 60, in _get_result
    return self.transport.execute(document, *args, **kwargs)
  File "/home/liushuai1/anaconda3/envs/tapa/lib/python3.10/site-packages/wandb/sdk/lib/gql_request.py", line 58, in execute
    request = self.session.post(self.url, **post_args)
  File "/home/liushuai1/anaconda3/envs/tapa/lib/python3.10/site-packages/requests/sessions.py", line 635, in post
    return self.request("POST", url, data=data, json=json, **kwargs)
  File "/home/liushuai1/anaconda3/envs/tapa/lib/python3.10/site-packages/requests/sessions.py", line 587, in request
    resp = self.send(prep, **send_kwargs)
  File "/home/liushuai1/anaconda3/envs/tapa/lib/python3.10/site-packages/requests/sessions.py", line 701, in send
    r = adapter.send(request, **kwargs)
  File "/home/liushuai1/anaconda3/envs/tapa/lib/python3.10/site-packages/requests/adapters.py", line 553, in send
    raise ConnectTimeout(e, request=request)
requests.exceptions.ConnectTimeout: HTTPSConnectionPool(host='api.wandb.ai', port=443): Max retries exceeded with url: /graphql (Caused by ConnectTimeoutError(<urllib3.connection.HTTPSConnection object at 0x7f371427a1a0>, 'Connection to api.wandb.ai timed out. (connect timeout=20)'))
2024-04-12 00:52:55,163 WARNING MainThread:200250 [wandb_init.py:init():1203] interrupted
Traceback (most recent call last):
  File "/home/liushuai1/anaconda3/envs/tapa/lib/python3.10/site-packages/wandb/sdk/wandb_init.py", line 1181, in init
    run = wi.init()
  File "/home/liushuai1/anaconda3/envs/tapa/lib/python3.10/site-packages/wandb/sdk/wandb_init.py", line 751, in init
    result = run_init_handle.wait(
  File "/home/liushuai1/anaconda3/envs/tapa/lib/python3.10/site-packages/wandb/sdk/lib/mailbox.py", line 283, in wait
    found, abandoned = self._slot._get_and_clear(timeout=wait_timeout)
  File "/home/liushuai1/anaconda3/envs/tapa/lib/python3.10/site-packages/wandb/sdk/lib/mailbox.py", line 130, in _get_and_clear
    if self._wait(timeout=timeout):
  File "/home/liushuai1/anaconda3/envs/tapa/lib/python3.10/site-packages/wandb/sdk/lib/mailbox.py", line 126, in _wait
    return self._event.wait(timeout=timeout)
  File "/home/liushuai1/anaconda3/envs/tapa/lib/python3.10/threading.py", line 607, in wait
    signaled = self._cond.wait(timeout)
  File "/home/liushuai1/anaconda3/envs/tapa/lib/python3.10/threading.py", line 324, in wait
    gotit = waiter.acquire(True, timeout)
KeyboardInterrupt
